Workbook

Sheet Orientações
A1: ORIENTAÇÕES GERAIS PARA PREENCHIMENTO DA PLANILHA DA DUPLA EVOLUTIVA
A3: 1. Essa a planilha foi elaborada a partir do verbete da Enciclopédia da Conscienciologia e do livro Manual da Dupla Evolutiva.
A4: 2. Sugerimos a leitura desse material para melhor entendimento da planilha.
A5: Download do verbete: | B5: RAIZ DO TEMPERAMENTO
A6: Download do livro: | B6: DUPLA EVOLUTIVA
A7: 3. A planilha está distribuida em 18 etapas, sendo as 7 primeiras etapas relacionadas ao verbete Raiz do Temperamento e as demais etapas ao livro da Dupla Evolutiva.
A8: 4. As planilhas estão interligadas entre si, e para garantir essa interrelação de dados optou-se em proteger algumas células.
A9: 5. As células que irão receber os dados (letras, textos ou números) estão desprotegidas.
A10: 6. Em algumas planilhas o pesquisador encontrata uma tarja vermelha com algumas informações referentes ao preenchimento. Para visualizar a informação é necessário colocar o cursor sobre essa tarja vermelha.
A11: 7. Algumas planilhas disponibilizam espaço para inclusão de textos. A célula desbloqueada para inclusão do texto pode estar abaixo ou ao lado da variável em análise.

Sheet 5 Variáveis Homem
A1: CATEGORIAS DA RAIZ DO TEMPERAMENTO DO HOMEM
A3: Tipo | B3: Variável | C3: Histórico | D3: Temperamento Predominante | F3: Variável predominante | G3: 1
F4: Apatia laboral
A5: ATIVIDADE | B5: Apatia laboral | F5: Vigor laboral
B6: Vigor laboral
B8: Motivação hedonista | F8: Variável predominante | G8: 1
B9: Motivação evolutiva | F9: Motivação hedonista
F10: Motivação evolutiva
B11: Volatividade de propóstitos | F11: Variável predominante | G11: 1
B12: Constância de propósitos | F12: Volatilidade de propósitos
F13: Constância de propósitos
B14: Flutuação da autodisponibilidade | F14: Variável predominante | G14: 1
B15: Perseverança da autodisponibilidade | F15: Flutuação da autodisponibilidade
F16: Perseverança da autodisponibilidade
B17: Atuação habitual calma | F17: Variável predominante | G17: 1
B18: Atuação habitual agitada | F18: Atuação habitual calma
F19: Atuação habitual agitada
B20: Alta adaptabilidade ao novo | F20: Variável predominante | G20: 1
B21: Lenta adaptabilidade ao novo | F21: Alta adaptabilidade ao novo
B22: Inexistente adaptabilidade ao novo | F22: Lenta adaptabilidade ao novo
F23: Inexistente adaptabilidade ao novo
A25: EMOCIONALIDADE | B25: Instabilidade emocional | F25: Variável predominante | G25: 1
B26: Estabilidade emocional | F26: Instabilidade emocional
F27: Estabilidade emocional
B28: Velocidade da resposta emocional com impulsividade | F28: Variável predominante | G28: 1
B29: Velocidade da resposta emocional com comedimento | F29: Velocidade de resposta emocional impulsiva
F30: Velocidade de resposta emocional comedida
B31: Intensidade da reação emocional amena | F31: Variável predominante | G31: 1
B32: Intensidade da reação emocional moderada | F32: Intensidade de reação emocional amena
B33: Intensidade da reação emocional explosiva | F33: Intensidade de reação emocional moderada
F34: Intensidade de reação emocional explosiva
B35: Predomínio do teor afetivo sadio | F35: Variável predominante | G35: 1
B36: Predomínio do teor afetivo patológico (medo, raiva, tristeza) | F36: Predomínio do teor afetivo sadio
F37: Predomínio do teor afetivo patológico
B38: Constância de humor | F38: Variável predominante | G38: 1
B39: Flutuação de humor | F39: Constância de humor
F40: Flutuação de humor
A41: PENSENIDADE | F41: Variável predominante | G41: 1
B42: Fluxo lento da pensenidade (bradipsiquismo) | F42: Bradipsiquismo pensênico
B43: Fluxo rápido da pensenidade (taquipsiquismo) | F43: Taquipsiquismo pensênico
...

Sheet 5 Variáveis Mulher
A1: CATEGORIAS DA RAIZ DO TEMPERAMENTO DO MULHER
A3: Tipo | B3: Variável | C3: Histórico | D3: Temperamento Predominante | F3: Variável predominante | G3: 1
F4: Apatia laboral
A5: ATIVIDADE | B5: Apatia laboral | F5: Vigor laboral
B6: Vigor laboral
B8: Motivação hedonista | F8: Variável predominante | G8: 1
B9: Motivação evolutiva | F9: Motivação hedonista
F10: Motivação evolutiva
B11: Volatividade de propóstitos | F11: Variável predominante | G11: 1
B12: Constância de propósitos | F12: Volatilidade de Propósitos
F13: Constância de propósitos
B14: Flutuação da autodisponibilidade | F14: Variável predominante | G14: 1
B15: Perseverança da autodisponibilidade | F15: Flutuação da autodisponibilidade
F16: Perseverança da autodisponibilidade
B17: Atuação habitual calma | F17: Variável predominante | G17: 1
B18: Atuação habitual agitada | F18: Atuação habitual calma
F19: Atuação habitual agitada
B20: Alta adaptabilidade ao novo | F20: Variável predominante | G20: 1
B21: Lenta adaptabilidade ao novo | F21: Alta adaptabilidade ao novo
B22: Inexistente adaptabilidade ao novo | F22: Lenta adaptabilidade ao novo
F23: Inexistente adaptabilidade ao novo
A25: EMOCIONALIDADE | B25: Instabilidade emocional | F25: Variável predominante | G25: 1
B26: Estabilidade emocional | F26: Instabilidade emocional
F27: Estabilidade emocional
B28: Velocidade da resposta emocional com impulsividade | F28: Variável predominante | G28: 1
B29: Velocidade da resposta emocional com comedimento | F29: Velocidade de resposta emocional impulsiva
F30: Velocidade de resposta emocional comedida
B31: Intensidade da reação emocional amena | F31: Variável predominante | G31: 1
B32: Intensidade da reação emocional moderada | F32: Intensidade de reação emocional amena
B33: Intensidade da reação emocional explosiva | F33: Intensidade de reação emocional moderada
F34: Intensidade de reação emocional explosiva
B35: Predomínio do teor afetivo sadio | F35: Variável predominante | G35: 1
B36: Predomínio do teor afetivo patológico (medo, raiva, tristeza) | F36: Predomínio do teor afetivo sadio
F37: Predomínio do teor afetivo patológico
B38: Constância de humor | F38: Variável predominante | G38: 1
B39: Flutuação de humor | F39: Constância de humor
F40: Flutuação de humor
A41: PENSENIDADE | F41: Variável predominante | G41: 1
B42: Fluxo lento da pensenidade (bradipsiquismo) | F42: Bradipsiquismo pensênico
B43: Fluxo rápido da pensenidade (taquipsiquismo) | F43: Taquipsiquismo pensênico
...

Sheet Comparativo 5 Variáveis
A1: COMPARATIVO DA DUPLA NA RAIZ DO TEMPERAMENTO
B3: HOMEM | D3: VARIÁVEIS | E3: MULHER
B4: ATIVIDADE | C4: =IF('5 Variáveis Homem'!G3=2, "sim", "não") -> não | D4: Apatia laboral | E4: =IF('5 Variáveis Mulher'!G3=2, "sim", "não") -> não | F4: ATIVIDADE | H4: =C4 -> não | I4: =E4 -> não | J4: =IF(H4="não", "0", "1") -> 0 | K4: =IF(I4="não", "0", "1") -> 0 | L4: =J4+K4 -> 0 | M4: =IF(L4=2, "Convergência", "")
C5: =IF('5 Variáveis Homem'!G3=3, "sim", "não") -> não | D5: Vigor laboral | E5: =IF('5 Variáveis Mulher'!G3=3, "sim", "não") -> não | H5: =C5 -> não | I5: =E5 -> não | J5: =IF(H5="não", "0", "1") -> 0 | K5: =IF(I5="não", "0", "1") -> 0 | L5: =J5+K5 -> 0 | M5: =IF(L5=2, "Convergência", "")
C6: =IF('5 Variáveis Homem'!G8=2, "sim", "não") -> não | D6: Motivação hedonista | E6: =IF('5 Variáveis Mulher'!G8=2, "sim", "não") -> não | H6: =C6 -> não | I6: =E6 -> não | J6: =IF(H6="não", "0", "1") -> 0 | K6: =IF(I6="não", "0", "1") -> 0 | L6: =J6+K6 -> 0 | M6: =IF(L6=2, "Convergência", "")
C7: =IF('5 Variáveis Homem'!G8=3, "sim", "não") -> não | D7: Motivação evolutiva | E7: =IF('5 Variáveis Mulher'!G8=3, "sim", "não") -> não | H7: =C7 -> não | I7: =E7 -> não | J7: =IF(H7="não", "0", "1") -> 0 | K7: =IF(I7="não", "0", "1") -> 0 | L7: =J7+K7 -> 0 | M7: =IF(L7=2, "Convergência", "")
C8: =IF('5 Variáveis Homem'!G11=2, "sim", "não") -> não | D8: Volatilidade de propósitos | E8: =IF('5 Variáveis Mulher'!G11=2, "sim", "não") -> não | H8: =C8 -> não | I8: =E8 -> não | J8: =IF(H8="não", "0", "1") -> 0 | K8: =IF(I8="não", "0", "1") -> 0 | L8: =J8+K8 -> 0 | M8: =IF(L8=2, "Convergência", "")
C9: =IF('5 Variáveis Homem'!G11=3, "sim", "não") -> não | D9: Constância de propósitos | E9: =IF('5 Variáveis Mulher'!G11=3, "sim", "não") -> não | H9: =C9 -> não | I9: =E9 -> não | J9: =IF(H9="não", "0", "1") -> 0 | K9: =IF(I9="não", "0", "1") -> 0 | L9: =J9+K9 -> 0 | M9: =IF(L9=2, "Convergência", "")
C10: =IF('5 Variáveis Homem'!G14=2, "sim", "não") -> não | D10: Flutuação da autodisponibilidade | E10: =IF('5 Variáveis Mulher'!G14=2, "sim", "não") -> não | H10: =C10 -> não | I10: =E10 -> não | J10: =IF(H10="não", "0", "1") -> 0 | K10: =IF(I10="não", "0", "1") -> 0 | L10: =J10+K10 -> 0 | M10: =IF(L10=2, "Convergência", "")
C11: =IF('5 Variáveis Homem'!G14=3, "sim", "não") -> não | D11: Perseverança da autodisponibilidade | E11: =IF('5 Variáveis Mulher'!G14=3, "sim", "não") -> não | H11: =C11 -> não | I11: =E11 -> não | J11: =IF(H11="não", "0", "1") -> 0 | K11: =IF(I11="não", "0", "1") -> 0 | L11: =J11+K11 -> 0 | M11: =IF(L11=2, "Convergência", "")
C12: =IF('5 Variáveis Homem'!G17=2, "sim", "não") -> não | D12: Atuação habitual calma | E12: =IF('5 Variáveis Mulher'!G17=2, "sim", "não") -> não | H12: =C12 -> não | I12: =E12 -> não | J12: =IF(H12="não", "0", "1") -> 0 | K12: =IF(I12="não", "0", "1") -> 0 | L12: =J12+K12 -> 0 | M12: =IF(L12=2, "Convergência", "")
C13: =IF('5 Variáveis Homem'!G17=3, "sim", "não") -> não | D13: Atuação habitual agitada | E13: =IF('5 Variáveis Mulher'!G17=3, "sim", "não") -> não | H13: =C13 -> não | I13: =E13 -> não | J13: =IF(H13="não", "0", "1") -> 0 | K13: =IF(I13="não", "0", "1") -> 0 | L13: =J13+K13 -> 0 | M13: =IF(L13=2, "Convergência", "")
B14: EMOCIONALIDADE | C14: =IF('5 Variáveis Homem'!G20=2, "sim", "não") -> não | D14: Alta adaptabilidade ao novo | E14: =IF('5 Variáveis Mulher'!G20=2, "sim", "não") -> não | F14: EMOCIONALIDADE | H14: =C14 -> não | I14: =E14 -> não | J14: =IF(H14="não", "0", "1") -> 0 | K14: =IF(I14="não", "0", "1") -> 0 | L14: =J14+K14 -> 0 | M14: =IF(L14=2, "Convergência", "")
C15: =IF('5 Variáveis Homem'!G20=3, "sim", "não") -> não | D15: Lenta adaptabilidade ao novo | E15: =IF('5 Variáveis Mulher'!G20=3, "sim", "não") -> não | H15: =C15 -> não | I15: =E15 -> não | J15: =IF(H15="não", "0", "1") -> 0 | K15: =IF(I15="não", "0", "1") -> 0 | L15: =J15+K15 -> 0 | M15: =IF(L15=2, "Convergência", "")
C16: =IF('5 Variáveis Homem'!G20=4, "sim", "não") -> não | D16: Inexistente adaptabilidade ao novo | E16: =IF('5 Variáveis Mulher'!G20=4, "sim", "não") -> não | H16: =C16 -> não | I16: =E16 -> não | J16: =IF(H16="não", "0", "1") -> 0 | K16: =IF(I16="não", "0", "1") -> 0 | L16: =J16+K16 -> 0 | M16: =IF(L16=2, "Convergência", "")
C17: =IF('5 Variáveis Homem'!G25=2, "sim", "não") -> não | D17: Instabilidade emocional | E17: =IF('5 Variáveis Mulher'!G25=2, "sim", "não") -> não | H17: =C17 -> não | I17: =E17 -> não | J17: =IF(H17="não", "0", "1") -> 0 | K17: =IF(I17="não", "0", "1") -> 0 | L17: =J17+K17 -> 0 | M17: =IF(L17=2, "Convergência", "")
C18: =IF('5 Variáveis Homem'!G25=3, "sim", "não") -> não | D18: Estabilidade emocional | E18: =IF('5 Variáveis Mulher'!G25=3, "sim", "não") -> não | H18: =C18 -> não | I18: =E18 -> não | J18: =IF(H18="não", "0", "1") -> 0 | K18: =IF(I18="não", "0", "1") -> 0 | L18: =J18+K18 -> 0 | M18: =IF(L18=2, "Convergência", "")
C19: =IF('5 Variáveis Homem'!G28=2, "sim", "não") -> não | D19: Velocidade de resposta emocional impulsiva | E19: =IF('5 Variáveis Mulher'!G28=2, "sim", "não") -> não | H19: =C19 -> não | I19: =E19 -> não | J19: =IF(H19="não", "0", "1") -> 0 | K19: =IF(I19="não", "0", "1") -> 0 | L19: =J19+K19 -> 0 | M19: =IF(L19=2, "Convergência", "")
C20: =IF('5 Variáveis Homem'!G28=3, "sim", "não") -> não | D20: Velocidade de resposta emocional comedida | E20: =IF('5 Variáveis Mulher'!G28=3, "sim", "não") -> não | H20: =C20 -> não | I20: =E20 -> não | J20: =IF(H20="não", "0", "1") -> 0 | K20: =IF(I20="não", "0", "1") -> 0 | L20: =J20+K20 -> 0 | M20: =IF(L20=2, "Convergência", "")
C21: =IF('5 Variáveis Homem'!G31=2, "sim", "não") -> não | D21: Intensidade de reação emocional amena | E21: =IF('5 Variáveis Mulher'!G31=2, "sim", "não") -> não | H21: =C21 -> não | I21: =E21 -> não | J21: =IF(H21="não", "0", "1") -> 0 | K21: =IF(I21="não", "0", "1") -> 0 | L21: =J21+K21 -> 0 | M21: =IF(L21=2, "Convergência", "")
C22: =IF('5 Variáveis Homem'!G31=3, "sim", "não") -> não | D22: Intensidade de reação emocional moderada | E22: =IF('5 Variáveis Mulher'!G31=3, "sim", "não") -> não | H22: =C22 -> não | I22: =E22 -> não | J22: =IF(H22="não", "0", "1") -> 0 | K22: =IF(I22="não", "0", "1") -> 0 | L22: =J22+K22 -> 0 | M22: =IF(L22=2, "Convergência", "")
C23: =IF('5 Variáveis Homem'!G31=4, "sim", "não") -> não | D23: Intensidade de reação emocional explosiva | E23: =IF('5 Variáveis Mulher'!G31=4, "sim", "não") -> não | H23: =C23 -> não | I23: =E23 -> não | J23: =IF(H23="não", "0", "1") -> 0 | K23: =IF(I23="não", "0", "1") -> 0 | L23: =J23+K23 -> 0 | M23: =IF(L23=2, "Convergência", "")
C24: =IF('5 Variáveis Homem'!G35=2, "sim", "não") -> não | D24: Predomínio do teor afetivo sadio | E24: =IF('5 Variáveis Mulher'!G35=2, "sim", "não") -> não | H24: =C24 -> não | I24: =E24 -> não | J24: =IF(H24="não", "0", "1") -> 0 | K24: =IF(I24="não", "0", "1") -> 0 | L24: =J24+K24 -> 0 | M24: =IF(L24=2, "Convergência", "")
C25: =IF('5 Variáveis Homem'!G35=3, "sim", "não") -> não | D25: Predomínio do teor afetivo patológico | E25: =IF('5 Variáveis Mulher'!G35=3, "sim", "não") -> não | H25: =C25 -> não | I25: =E25 -> não | J25: =IF(H25="não", "0", "1") -> 0 | K25: =IF(I25="não", "0", "1") -> 0 | L25: =J25+K25 -> 0 | M25: =IF(L25=2, "Convergência", "")
C26: =IF('5 Variáveis Homem'!G38=2, "sim", "não") -> não | D26: Constância de humor | E26: =IF('5 Variáveis Mulher'!G38=2, "sim", "não") -> não | H26: =C26 -> não | I26: =E26 -> não | J26: =IF(H26="não", "0", "1") -> 0 | K26: =IF(I26="não", "0", "1") -> 0 | L26: =J26+K26 -> 0 | M26: =IF(L26=2, "Convergência", "")
C27: =IF('5 Variáveis Homem'!G38=3, "sim", "não") -> não | D27: Flutuação de humor | E27: =IF('5 Variáveis Mulher'!G38=3, "sim", "não") -> não | H27: =C27 -> não | I27: =E27 -> não | J27: =IF(H27="não", "0", "1") -> 0 | K27: =IF(I27="não", "0", "1") -> 0 | L27: =J27+K27 -> 0 | M27: =IF(L27=2, "Convergência", "")
B28: PENSENIDADE | C28: =IF('5 Variáveis Homem'!G41=2, "sim", "não") -> não | D28: Bradipsiquismo pensênico | E28: =IF('5 Variáveis Mulher'!G41=2, "sim", "não") -> não | F28: PENSENIDADE | H28: =C28 -> não | I28: =E28 -> não | J28: =IF(H28="não", "0", "1") -> 0 | K28: =IF(I28="não", "0", "1") -> 0 | L28: =J28+K28 -> 0 | M28: =IF(L28=2, "Convergência", "")
C29: =IF('5 Variáveis Homem'!G41=3, "sim", "não") -> não | D29: Taquipsiquismo pensênico | E29: =IF('5 Variáveis Mulher'!G41=3, "sim", "não") -> não | H29: =C29 -> não | I29: =E29 -> não | J29: =IF(H29="não", "0", "1") -> 0 | K29: =IF(I29="não", "0", "1") -> 0 | L29: =J29+K29 -> 0 | M29: =IF(L29=2, "Convergência", "")
C30: =IF('5 Variáveis Homem'!G44=2, "sim", "não") -> não | D30: Fixação pensênica | E30: =IF('5 Variáveis Mulher'!G44=2, "sim", "não") -> não | H30: =C30 -> não | I30: =E30 -> não | J30: =IF(H30="não", "0", "1") -> 0 | K30: =IF(I30="não", "0", "1") -> 0 | L30: =J30+K30 -> 0 | M30: =IF(L30=2, "Convergência", "")
C31: =IF('5 Variáveis Homem'!G44=3, "sim", "não") -> não | D31: Flexibilidade pensênica | E31: =IF('5 Variáveis Mulher'!G44=3, "sim", "não") -> não | H31: =C31 -> não | I31: =E31 -> não | J31: =IF(H31="não", "0", "1") -> 0 | K31: =IF(I31="não", "0", "1") -> 0 | L31: =J31+K31 -> 0 | M31: =IF(L31=2, "Convergência", "")
C32: =IF('5 Variáveis Homem'!G47=2, "sim", "não") -> não | D32: Propensão a distração mental | E32: =IF('5 Variáveis Mulher'!G47=2, "sim", "não") -> não | H32: =C32 -> não | I32: =E32 -> não | J32: =IF(H32="não", "0", "1") -> 0 | K32: =IF(I32="não", "0", "1") -> 0 | L32: =J32+K32 -> 0 | M32: =IF(L32=2, "Convergência", "")
C33: =IF('5 Variáveis Homem'!G31=3, "sim", "não") -> não | D33: Propensão a concentração mental | E33: =IF('5 Variáveis Mulher'!G31=3, "sim", "não") -> não | H33: =C33 -> não | I33: =E33 -> não | J33: =IF(H33="não", "0", "1") -> 0 | K33: =IF(I33="não", "0", "1") -> 0 | L33: =J33+K33 -> 0 | M33: =IF(L33=2, "Convergência", "")
C34: =IF('5 Variáveis Homem'!G51=2, "sim", "não") -> não | D34: Inclinação à superficialidade | E34: =IF('5 Variáveis Mulher'!G51=2, "sim", "não") -> não | H34: =C34 -> não | I34: =E34 -> não | J34: =IF(H34="não", "0", "1") -> 0 | K34: =IF(I34="não", "0", "1") -> 0 | L34: =J34+K34 -> 0 | M34: =IF(L34=2, "Convergência", "")
C35: =IF('5 Variáveis Homem'!G51=3, "sim", "não") -> não | D35: Inclinação à profundidade reflexiva | E35: =IF('5 Variáveis Mulher'!G51=3, "sim", "não") -> não | H35: =C35 -> não | I35: =E35 -> não | J35: =IF(H35="não", "0", "1") -> 0 | K35: =IF(I35="não", "0", "1") -> 0 | L35: =J35+K35 -> 0 | M35: =IF(L35=2, "Convergência", "")
C36: =IF('5 Variáveis Homem'!G53=2, "sim", "não") -> não | D36: Padrão holopensênico benévolo | E36: =IF('5 Variáveis Mulher'!G53=2, "sim", "não") -> não | H36: =C36 -> não | I36: =E36 -> não | J36: =IF(H36="não", "0", "1") -> 0 | K36: =IF(I36="não", "0", "1") -> 0 | L36: =J36+K36 -> 0 | M36: =IF(L36=2, "Convergência", "")
C37: =IF('5 Variáveis Homem'!G53=3, "sim", "não") -> não | D37: Padrão holopensênico malévolo | E37: =IF('5 Variáveis Mulher'!G53=3, "sim", "não") -> não | H37: =C37 -> não | I37: =E37 -> não | J37: =IF(H37="não", "0", "1") -> 0 | K37: =IF(I37="não", "0", "1") -> 0 | L37: =J37+K37 -> 0 | M37: =IF(L37=2, "Convergência", "")
B38: PERCEPTIBILIDADE | C38: =IF('5 Variáveis Homem'!G57=2, "sim", "não") -> não | D38: Amplo limiar de responsividade aos estímulos | E38: =IF('5 Variáveis Mulher'!G57=2, "sim", "não") -> não | F38: PERCEPTIBILIDADE | H38: =C38 -> não | I38: =E38 -> não | J38: =IF(H38="não", "0", "1") -> 0 | K38: =IF(I38="não", "0", "1") -> 0 | L38: =J38+K38 -> 0 | M38: =IF(L38=2, "Convergência", "")
C39: =IF('5 Variáveis Homem'!G57=3, "sim", "não") -> não | D39: Restrito limiar de responsividade aos estímulos | E39: =IF('5 Variáveis Mulher'!G57=3, "sim", "não") -> não | H39: =C39 -> não | I39: =E39 -> não | J39: =IF(H39="não", "0", "1") -> 0 | K39: =IF(I39="não", "0", "1") -> 0 | L39: =J39+K39 -> 0 | M39: =IF(L39=2, "Convergência", "")
C40: =IF('5 Variáveis Homem'!G60=2, "sim", "não") -> não | D40: Resposta rápida aos perceptos | E40: =IF('5 Variáveis Mulher'!G60=2, "sim", "não") -> não | H40: =C40 -> não | I40: =E40 -> não | J40: =IF(H40="não", "0", "1") -> 0 | K40: =IF(I40="não", "0", "1") -> 0 | L40: =J40+K40 -> 0 | M40: =IF(L40=2, "Convergência", "")
C41: =IF('5 Variáveis Homem'!G60=3, "sim", "não") -> não | D41: Resposta lenta aos perceptos | E41: =IF('5 Variáveis Mulher'!G60=3, "sim", "não") -> não | H41: =C41 -> não | I41: =E41 -> não | J41: =IF(H41="não", "0", "1") -> 0 | K41: =IF(I41="não", "0", "1") -> 0 | L41: =J41+K41 -> 0 | M41: =IF(L41=2, "Convergência", "")
...

Sheet 50 Categorias Homem
B1: 50 CATEGORIAS DO TEMPERAMENTO HUMANO - HOMEM
B2: Assinale com "x" a variável que se aproxima ao seu temperamento
B3: Homeostático | D3: Nº | E3: Nosográfico | G3: Homeostático | I3: Nº | J3: Nosográfico
B5: Aberto | D5: 1 | E5: x | F5: Fechado | G5: Heurístico | I5: 26 | K5: Plagiador
B6: Acolhedor | C6: x | D6: 2 | F6: Irascível | G6: Intelectual | I6: 27 | K6: Psicomotor
B7: Alegre | C7: x | D7: 3 | F7: Sorumbático | G7: Interdependente | I7: 28 | K7: Megadependente
B8: Altruístico | C8: x | D8: 4 | F8: Feudal | G8: Large | I8: 29 | K8: Miserê
B9: Amadurecido | C9: x | D9: 5 | F9: Imaturo | G9: Liderológico | I9: 30 | K9: Submisso
B10: Antecipador | C10: x | D10: 6 | F10: Procrastinador | G10: Megaeuforizante | I10: 31 | K10: Megassediante
B11: Anticonflitivo | C11: x | D11: 7 | F11: Omniconflitivo | G11: Morígero | I11: 32 | K11: Imorigerado
B12: Assertivo | C12: x | D12: 8 | F12: Leniente | G12: Neofílico | I12: 33 | K12: Neofóbico
B13: Assistencial | D13: 9 | F13: Petulante | G13: Omnicrítico | I13: 34 | K13: Manipulável
B14: Autodesassediado | D14: 10 | F14: Heterassediador | G14: Otimista | I14: 35 | J14: x | K14: Pessimista
B15: Autoimperdoador | D15: 11 | F15: Autoindulgente | G15: Paciente | I15: 36 | J15: x | K15: Irritadiço
B16: Benigno | C16: x | D16: 12 | F16: Malévolo | G16: Pacifista | I16: 37 | J16: x | K16: Belicista
B17: Bibliofilico | D17: 13 | F17: Bibliofóbico | G17: Parapsíquico | H17: x | I17: 38 | K17: Eletronótico
B18: Cogniciofílico | D18: 14 | F18: Néscio | G18: Ponderado | H18: x | I18: 39 | K18: Impulsivo
B19: Conciliador | D19: 15 | F19: Caústico | G19: Racional | H19: x | I19: 40 | K19: Emocional
B20: Cosmovisiológico | D20: 16 | F20: Monovisiológico | G20: Revitalizante | I20: 41 | K20: Depressivo
B21: Detalhista | D21: 17 | F21: Perfeccionista | G21: Sereno | I21: 42 | K21: Ansioso
B22: Doador | D22: 18 | F22: Egocêntrico | G22: Superavitário | I22: 43 | K22: Deficitário
B23: Educador | D23: 19 | F23: Repressor | G23: Taquipsíquico | I23: 44 | K23: Bradipsíquico
B24: Equilibrado | D24: 20 | F24: Baratrosférico | G24: Tarístico | I24: 45 | K24: Taconístico
B25: Exaustivo | D25: 21 | F25: Superficial | G25: Tenepessável | I25: 46 | K25: Religioso
B26: Exemplarístico | D26: 22 | F26: Vexaminoso | G26: Traforístico | I26: 47 | K26: Trafarístico
B27: Extrovertido | D27: 23 | F27: Introvertido | G27: Universalista | I27: 48 | K27: Monárquico
B28: Fitofílico | D28: 24 | F28: Fitofóbico | G28: Voliciolínico | I28: 49 | K28: Voliciopático
B29: Flexível | D29: 25 | F29: Teimoso | G29: Zoofílico | I29: 50 | K29: Zoofóbico
G53: Homeostático | H53: =COUNTIF(C5:C29, "x")+COUNTIF(H5:H29, "x") -> 11
G54: Nosográfico | H54: =COUNTIF(E5:E29, "x")+COUNTIF(J5:J29, "x") -> 4

Sheet 50 Categorias Mulher
B1: 50 CATEGORIAS DO TEMPERAMENTO HUMANO - MULHER
B2: Assinale com "x" a variável que se aproxima ao seu temperamento
B3: Homeostático | D3: Nº | E3: Nosográfico | G3: Homeostático | I3: Nº | J3: Nosográfico
B5: Aberto | D5: 1 | F5: Fechado | G5: Heurístico | I5: 26 | K5: Plagiador
B6: Acolhedor | D6: 2 | F6: Irascível | G6: Intelectual | I6: 27 | K6: Psicomotor
B7: Alegre | D7: 3 | F7: Sorumbático | G7: Interdependente | I7: 28 | K7: Megadependente
B8: Altruístico | D8: 4 | F8: Feudal | G8: Large | I8: 29 | K8: Miserê
B9: Amadurecido | D9: 5 | F9: Imaturo | G9: Liderológico | I9: 30 | K9: Submisso
B10: Antecipador | D10: 6 | F10: Procrastinador | G10: Megaeuforizante | I10: 31 | K10: Megassediante
B11: Anticonflitivo | D11: 7 | F11: Omniconflitivo | G11: Morígero | I11: 32 | K11: Imorigerado
B12: Assertivo | D12: 8 | F12: Leniente | G12: Neofílico | I12: 33 | K12: Neofóbico
B13: Assistencial | D13: 9 | F13: Petulante | G13: Omnicrítico | I13: 34 | K13: Manipulável
B14: Autodesassediado | D14: 10 | F14: Heterassediador | G14: Otimista | I14: 35 | K14: Pessimista
B15: Autoimperdoador | D15: 11 | F15: Autoindulgente | G15: Paciente | I15: 36 | K15: Irritadiço
B16: Benigno | D16: 12 | F16: Malévolo | G16: Pacifista | I16: 37 | K16: Belicista
... B29: Flexível | D29: 25 | F29: Teimoso | G29: Zoofílico | I29: 50 | K29: Zoofóbico
N43: Homeostático | O43: =COUNTIF(C5:C29, "x")+COUNTIF(H5:H29, "x") -> 0
N44: Nosográfico | O44: =COUNTIF(E5:E29, "x")+COUNTIF(J5:J29, "x") -> 0

Sheet Comparativo 50 Categorias
B1: COMPARATIVO DA DUPLA NAS 50 CATEGORIAS DO TEMPERAMENTO HUMANO
B2: A cor verde (homeostático) e a cor vermelha (nosográfico), na variável, indica a convergência do temperamento da Dupla Evolutiva
B3: Homeostático | D3: Nº | E3: Nosográfico | G3: Homeostático | I3: Nº | J3: Nosográfico | O3: HH | P3: MH | Q3: Soma | R3: HN | S3: MN | T3: Soma | U3: HH | V3: MH | W3: Soma | X3: HN | Y3: MN | Z3: Soma
B5: Aberto | C5: =IF(Q5=2,"S", "") | D5: 1 | E5: =IF(T5=2, "S", "") | F5: Fechado | G5: Heurístico | H5: =IF(W5=2, "S", "") | I5: 26 | J5: =IF(Z5=2, "S", "") | K5: Plagiador | O5: ='50 Categorias Homem'!C5 -> 0 | P5: ='50 Categorias Mulher'!C5 -> 0 | Q5: =COUNTIF(O5:P5,"X") -> 0 | R5: ='50 Categorias Homem'!E5 -> x | S5: ='50 Categorias Mulher'!E5 -> 0 | T5: =COUNTIF(R5:S5, "x") -> 1 | U5: ='50 Categorias Homem'!H5 -> 0 | V5: ='50 Categorias Mulher'!H5 -> 0 | W5: =COUNTIF(U5:V5, "x") -> 0 | X5: ='50 Categorias Homem'!J5 -> 0 | Y5: ='50 Categorias Mulher'!J5 -> 0 | Z5: =COUNTIF(X5:Y5, "x") -> 0
B6: Acolhedor | C6: =IF(Q6=2,"S", "") | D6: 2 | E6: =IF(T6=2, "S", "") | F6: Irascível | G6: Intelectual | H6: =IF(W6=2, "S", "") | I6: 27 | J6: =IF(Z6=2, "S", "") | K6: Psicomotor | O6: ='50 Categorias Homem'!C6 -> x | P6: ='50 Categorias Mulher'!C6 -> 0 | Q6: =COUNTIF(O6:P6,"X") -> 1 | R6: ='50 Categorias Homem'!E6 -> 0 | S6: ='50 Categorias Mulher'!E6 -> 0 | T6: =COUNTIF(R6:S6, "x") -> 0 | U6: ='50 Categorias Homem'!H6 -> 0 | V6: ='50 Categorias Mulher'!H6 -> 0 | W6: =COUNTIF(U6:V6, "x") -> 0 | X6: ='50 Categorias Homem'!J6 -> 0 | Y6: ='50 Categorias Mulher'!J6 -> 0 | Z6: =COUNTIF(X6:Y6, "x") -> 0
B7: Alegre | C7: =IF(Q7=2,"S", "") | D7: 3 | E7: =IF(T7=2, "S", "") | F7: Sorumbático | G7: Interdependente | H7: =IF(W7=2, "S", "") | I7: 28 | J7: =IF(Z7=2, "S", "") | K7: Megadependente | O7: ='50 Categorias Homem'!C7 -> x | P7: ='50 Categorias Mulher'!C7 -> 0 | Q7: =COUNTIF(O7:P7,"X") -> 1 | R7: ='50 Categorias Homem'!E7 -> 0 | S7: ='50 Categorias Mulher'!E7 -> 0 | T7: =COUNTIF(R7:S7, "x") -> 0 | U7: ='50 Categorias Homem'!H7 -> 0 | V7: ='50 Categorias Mulher'!H7 -> 0 | W7: =COUNTIF(U7:V7, "x") -> 0 | X7: ='50 Categorias Homem'!J7 -> 0 | Y7: ='50 Categorias Mulher'!J7 -> 0 | Z7: =COUNTIF(X7:Y7, "x") -> 0
B8: Altruístico | C8: =IF(Q8=2,"S", "") | D8: 4 | E8: =IF(T8=2, "S", "") | F8: Feudal | G8: Large | H8: =IF(W8=2, "S", "") | I8: 29 | J8: =IF(Z8=2, "S", "") | K8: Miserê | O8: ='50 Categorias Homem'!C8 -> x | P8: ='50 Categorias Mulher'!C8 -> 0 | Q8: =COUNTIF(O8:P8,"X") -> 1 | R8: ='50 Categorias Homem'!E8 -> 0 | S8: ='50 Categorias Mulher'!E8 -> 0 | T8: =COUNTIF(R8:S8, "x") -> 0 | U8: ='50 Categorias Homem'!H8 -> 0 | V8: ='50 Categorias Mulher'!H8 -> 0 | W8: =COUNTIF(U8:V8, "x") -> 0 | X8: ='50 Categorias Homem'!J8 -> 0 | Y8: ='50 Categorias Mulher'!J8 -> 0 | Z8: =COUNTIF(X8:Y8, "x") -> 0
B9: Amadurecido | C9: =IF(Q9=2,"S", "") | D9: 5 | E9: =IF(T9=2, "S", "") | F9: Imaturo | G9: Liderológico | H9: =IF(W9=2, "S", "") | I9: 30 | J9: =IF(Z9=2, "S", "") | K9: Submisso | O9: ='50 Categorias Homem'!C9 -> x | P9: ='50 Categorias Mulher'!C9 -> 0 | Q9: =COUNTIF(O9:P9,"X") -> 1 | R9: ='50 Categorias Homem'!E9 -> 0 | S9: ='50 Categorias Mulher'!E9 -> 0 | T9: =COUNTIF(R9:S9, "x") -> 0 | U9: ='50 Categorias Homem'!H9 -> 0 | V9: ='50 Categorias Mulher'!H9 -> 0 | W9: =COUNTIF(U9:V9, "x") -> 0 | X9: ='50 Categorias Homem'!J9 -> 0 | Y9: ='50 Categorias Mulher'!J9 -> 0 | Z9: =COUNTIF(X9:Y9, "x") -> 0
B10: Antecipador | C10: =IF(Q10=2,"S", "") | D10: 6 | E10: =IF(T10=2, "S", "") | F10: Procrastinador | G10: Megaeuforizante | H10: =IF(W10=2, "S", "") | I10: 31 | J10: =IF(Z10=2, "S", "") | K10: Megassediante | O10: ='50 Categorias Homem'!C10 -> x | P10: ='50 Categorias Mulher'!C10 -> 0 | Q10: =COUNTIF(O10:P10,"X") -> 1 | R10: ='50 Categorias Homem'!E10 -> 0 | S10: ='50 Categorias Mulher'!E10 -> 0 | T10: =COUNTIF(R10:S10, "x") -> 0 | U10: ='50 Categorias Homem'!H10 -> 0 | V10: ='50 Categorias Mulher'!H10 -> 0 | W10: =COUNTIF(U10:V10, "x") -> 0 | X10: ='50 Categorias Homem'!J10 -> 0 | Y10: ='50 Categorias Mulher'!J10 -> 0 | Z10: =COUNTIF(X10:Y10, "x") -> 0
B11: Anticonflitivo | C11: =IF(Q11=2,"S", "") | D11: 7 | E11: =IF(T11=2, "S", "") | F11: Omniconflitivo | G11: Morígero | H11: =IF(W11=2, "S", "") | I11: 32 | J11: =IF(Z11=2, "S", "") | K11: Imorigerado | O11: ='50 Categorias Homem'!C11 -> x | P11: ='50 Categorias Mulher'!C11 -> 0 | Q11: =COUNTIF(O11:P11,"X") -> 1 | R11: ='50 Categorias Homem'!E11 -> 0 | S11: ='50 Categorias Mulher'!E11 -> 0 | T11: =COUNTIF(R11:S11, "x") -> 0 | U11: ='50 Categorias Homem'!H11 -> 0 | V11: ='50 Categorias Mulher'!H11 -> 0 | W11: =COUNTIF(U11:V11, "x") -> 0 | X11: ='50 Categorias Homem'!J11 -> 0 | Y11: ='50 Categorias Mulher'!J11 -> 0 | Z11: =COUNTIF(X11:Y11, "x") -> 0
B12: Assertivo | C12: =IF(Q12=2,"S", "") | D12: 8 | E12: =IF(T12=2, "S", "") | F12: Leniente | G12: Neofílico | H12: =IF(W12=2, "S", "") | I12: 33 | J12: =IF(Z12=2, "S", "") | K12: Neofóbico | O12: ='50 Categorias Homem'!C12 -> x | P12: ='50 Categorias Mulher'!C12 -> 0 | Q12: =COUNTIF(O12:P12,"X") -> 1 | R12: ='50 Categorias Homem'!E12 -> 0 | S12: ='50 Categorias Mulher'!E12 -> 0 | T12: =COUNTIF(R12:S12, "x") -> 0 | U12: ='50 Categorias Homem'!H12 -> 0 | V12: ='50 Categorias Mulher'!H12 -> 0 | W12: =COUNTIF(U12:V12, "x") -> 0 | X12: ='50 Categorias Homem'!J12 -> 0 | Y12: ='50 Categorias Mulher'!J12 -> 0 | Z12: =COUNTIF(X12:Y12, "x") -> 0
B13: Assistencial | C13: =IF(Q13=2,"S", "") | D13: 9 | E13: =IF(T13=2, "S", "") | F13: Petulante | G13: Omnicrítico | H13: =IF(W13=2, "S", "") | I13: 34 | J13: =IF(Z13=2, "S", "") | K13: Manipulável | O13: ='50 Categorias Homem'!C13 -> 0 | P13: ='50 Categorias Mulher'!C13 -> 0 | Q13: =COUNTIF(O13:P13,"X") -> 0 | R13: ='50 Categorias Homem'!E13 -> 0 | S13: ='50 Categorias Mulher'!E13 -> 0 | T13: =COUNTIF(R13:S13, "x") -> 0 | U13: ='50 Categorias Homem'!H13 -> 0 | V13: ='50 Categorias Mulher'!H13 -> 0 | W13: =COUNTIF(U13:V13, "x") -> 0 | X13: ='50 Categorias Homem'!J13 -> 0 | Y13: ='50 Categorias Mulher'!J13 -> 0 | Z13: =COUNTIF(X13:Y13, "x") -> 0
B14: Autodesassediado | C14: =IF(Q14=2,"S", "") | D14: 10 | E14: =IF(T14=2, "S", "") | F14: Heterassediador | G14: Otimista | H14: =IF(W14=2, "S", "") | I14: 35 | J14: =IF(Z14=2, "S", "") | K14: Pessimista | O14: ='50 Categorias Homem'!C14 -> 0 | P14: ='50 Categorias Mulher'!C14 -> 0 | Q14: =COUNTIF(O14:P14,"X") -> 0 | R14: ='50 Categorias Homem'!E14 -> 0 | S14: ='50 Categorias Mulher'!E14 -> 0 | T14: =COUNTIF(R14:S14, "x") -> 0 | U14: ='50 Categorias Homem'!H14 -> 0 | V14: ='50 Categorias Mulher'!H14 -> 0 | W14: =COUNTIF(U14:V14, "x") -> 0 | X14: ='50 Categorias Homem'!J14 -> x | Y14: ='50 Categorias Mulher'!J14 -> 0 | Z14: =COUNTIF(X14:Y14, "x") -> 1
B15: Autoimperdoador | C15: =IF(Q15=2,"S", "") | D15: 11 | E15: =IF(T15=2, "S", "") | F15: Autoindulgente | G15: Paciente | H15: =IF(W15=2, "S", "") | I15: 36 | J15: =IF(Z15=2, "S", "") | K15: Irritadiço | O15: ='50 Categorias Homem'!C15 -> 0 | P15: ='50 Categorias Mulher'!C15 -> 0 | Q15: =COUNTIF(O15:P15,"X") -> 0 | R15: ='50 Categorias Homem'!E15 -> 0 | S15: ='50 Categorias Mulher'!E15 -> 0 | T15: =COUNTIF(R15:S15, "x") -> 0 | U15: ='50 Categorias Homem'!H15 -> 0 | V15: ='50 Categorias Mulher'!H15 -> 0 | W15: =COUNTIF(U15:V15, "x") -> 0 | X15: ='50 Categorias Homem'!J15 -> x | Y15: ='50 Categorias Mulher'!J15 -> 0 | Z15: =COUNTIF(X15:Y15, "x") -> 1
B16: Benigno | C16: =IF(Q16=2,"S", "") | D16: 12 | E16: =IF(T16=2, "S", "") | F16: Malévolo | G16: Pacifista | H16: =IF(W16=2, "S", "") | I16: 37 | J16: =IF(Z16=2, "S", "") | K16: Belicista | O16: ='50 Categorias Homem'!C16 -> x | P16: ='50 Categorias Mulher'!C16 -> 0 | Q16: =COUNTIF(O16:P16,"X") -> 1 | R16: ='50 Categorias Homem'!E16 -> 0 | S16: ='50 Categorias Mulher'!E16 -> 0 | T16: =COUNTIF(R16:S16, "x") -> 0 | U16: ='50 Categorias Homem'!H16 -> 0 | V16: ='50 Categorias Mulher'!H16 -> 0 | W16: =COUNTIF(U16:V16, "x") -> 0 | X16: ='50 Categorias Homem'!J16 -> x | Y16: ='50 Categorias Mulher'!J16 -> 0 | Z16: =COUNTIF(X16:Y16, "x") -> 1
... B29: Flexível | C29: =IF(Q29=2,"S", "") | D29: 25 | E29: =IF(T29=2, "S", "") | F29: Teimoso | G29: Zoofílico | H29: =IF(W29=2, "S", "") | I29: 50 | J29: =IF(Z29=2, "S", "") | K29: Zoofóbico | O29: ='50 Categorias Homem'!C29 -> 0 | P29: ='50 Categorias Mulher'!C29 -> 0 | Q29: =COUNTIF(O29:P29,"X") -> 0 | R29: ='50 Categorias Homem'!E29 -> 0 | S29: ='50 Categorias Mulher'!E29 -> 0 | T29: =COUNTIF(R29:S29, "x") -> 0 | U29: ='50 Categorias Homem'!H29 -> 0 | V29: ='50 Categorias Mulher'!H29 -> 0 | W29: =COUNTIF(U29:V29, "x") -> 0 | X29: ='50 Categorias Homem'!J29 -> 0 | Y29: ='50 Categorias Mulher'!J29 -> 0 | Z29: =COUNTIF(X29:Y29, "x") -> 0
B52: 5 Variáveis
B53: ='Comparativo 5 Variáveis'!D80 -> Convergência | C53: ='Comparativo 5 Variáveis'!E80 -> 0 | D53: =C53/C55 -> 0
B54: ='Comparativo 5 Variáveis'!D81 -> Divergência | C54: ='Comparativo 5 Variáveis'!E81 -> 26 | D54: =C54/C55 -> 1
B55: 50 Categorias | C55: =SUM(C53:C54) -> 26
B56: Homeostático | C56: =COUNTIF(C5:C29, "S")+COUNTIF(H5:H29, "s") -> 0 | D56: =C56/C58 -> #DIV/0!
B57: Nosográfico | C57: =COUNTIF(E5:E29, "s")+COUNTIF(J5:J29, "s") -> 0 | D57: =C57/C58 -> #DIV/0!
C58: =SUM(C56:C57) -> 0

Sheet Questionologia
A1: QUESTIONAMENTO
A3: 1. Vocês identificaram a raiz do próprio temperamento? Caso positivo, sintetizem seus temperamentos.
A4: Justifique aqui
A6: 2. Vocês sabem aplicar estes conhecimentos nas neoconquistas evolutivas?
A7: Justifique aqui
A11: A PESQUISA, IDENTIFICAÇÃO E APLICAÇÃO DA AUTOCOGNIÇÃO
A12: QUANTO À RAIZ DO PRÓPRIO TEMPERAMENTO
A13: DEVE, LOGICAMENTE, SER PONTO ESSENCIAL PARA
A14: A AUTOMATURIDADE DA CONSCIÊNCIA INTERMISSIVISTA.

Sheet Autenticidade Afetiva Homem
A1: AUTENTICIDADE AFETIVA - HOMEM
A2: O teste da vivência do nível da autêntica afetividade – o amor real do casal íntimo – pela consciência que compõe uma dupla evolutiva, pode ser desenvolvido pelas respostas realistas a estas 25 questões
A4: 1. Acoplamento. Já fiz acoplamento áurico diretamente com essa conscin-parceira? | C4: =IF(D4, "Sim", "") | D4: FALSE
A5: 2. Alcova. Mantenho sempre, de minha parte, a blindagem energética de nossa alcova? | C5: =IF(D5, "Sim", "") | D5: FALSE
A6: 3. Assédios. Eu a assisto na superação de possíveis assédios inconscientes? | C6: =IF(D6, "Sim", "") | D6: FALSE
A7: 4. Assins. Promovo assimilações simpáticas (assins) com a intenção de auscultar-lhe as energias conscienciais e o nível da saúde? | C7: =IF(D7, "Sim", "") | D7: FALSE
A8: 5. Carinho. Ofereço-lhe carinho e atenção após instalar o estado vibracional profilático? | C8: =IF(D8, "Sim", "") | D8: FALSE
A9: 6. Clarividências. Patrocino clarividências faciais para minha companhia entrever a dimensão energética (dimener)? | C9: =IF(D9, "Sim", "") | D9: FALSE
A10: 7. Cosmoconsciência. Já contribuí, até agora, para fazê-la expandir a própria consciência? | C10: =IF(D10, "Sim", "") | D10: FALSE
A11: 8. Descompensações. Já identifiquei-lhe as descompensações sistêmicas de energia ou os seus bloqueios energéticos? | C11: =IF(D11, "Sim", "") | D11: FALSE
A12: 9. EV. Venho cooperando realmente para que ela domine, por si mesma, a instalação do estado vibracional (EV)? | C12: =IF(D12, "Sim", "") | D12: FALSE
A13: 10. Holochacra. Já a ajudei a equilibrar e flexibilizar o próprio holochacra? | C13: =IF(D13, "Sim", "") | D13: FALSE
A14: 11. Holorgasmo. Já procurei dar-lhe, pelo menos, um holorgasmo (raro) até o momento? | C14: =IF(D14, "Sim", "") | D14: FALSE
A15: 12. Isca. Já servi de isca consciencial lúcida a fim de promover os desassédios dela? | C15: =IF(D15, "Sim", "") | D15: FALSE
... A28: 25. Trafores. Já fiz uma exposição sincera dos megatrafores, ou trafores que já identifiquei nela ou dela, a fim de que ela os empregue no combate aos seus trafares pessoais? | C28: =IF(D28, "Sim", "") | D28: FALSE
A30: Se o interessado ou interessada respondeu sim a, pelo menos, 12 destas questões, a sua afetividade prática ou vivida, é de bom nível conscienciológico, holossomático e parapsíquico. | B30: Total | C30: =F30 -> 0 | E30: Sim | F30: =COUNTIF(C4:C28, "sim") -> 0
E31: Não | F31: =25-F30 -> 25

Sheet Autenticidade Afetiva Mulher
A1: AUTENTICIDADE AFETIVA - MULHER
A2: O teste da vivência do nível da autêntica afetividade – o amor real do casal íntimo – pela consciência que compõe uma dupla evolutiva, pode ser desenvolvido pelas respostas realistas a estas 25 questões
A4: 1. Acoplamento. Já fiz acoplamento áurico diretamente com essa conscin-parceira? | C4: =IF(D4, "Sim", "") | D4: FALSE
A5: 2. Alcova. Mantenho sempre, de minha parte, a blindagem energética de nossa alcova? | C5: =IF(D5, "Sim", "") | D5: FALSE
A6: 3. Assédios. Eu a assisto na superação de possíveis assédios inconscientes? | C6: =IF(D6, "Sim", "") | D6: FALSE
A7: 4. Assins. Promovo assimilações simpáticas (assins) com a intenção de auscultar-lhe as energias conscienciais e o nível da saúde? | C7: =IF(D7, "Sim", "") | D7: FALSE
A8: 5. Carinho. Ofereço-lhe carinho e atenção após instalar o estado vibracional profilático? | C8: =IF(D8, "Sim", "") | D8: FALSE
A9: 6. Clarividências. Patrocino clarividências faciais para minha companhia entrever a dimensão energética (dimener)? | C9: =IF(D9, "Sim", "") | D9: FALSE
A10: 7. Cosmoconsciência. Já contribuí, até agora, para fazê-la expandir a própria consciência? | C10: =IF(D10, "Sim", "") | D10: FALSE
A11: 8. Descompensações. Já identifiquei-lhe as descompensações sistêmicas de energia ou os seus bloqueios energéticos? | C11: =IF(D11, "Sim", "") | D11: FALSE
A12: 9. EV. Venho cooperando realmente para que ela domine, por si mesma, a instalação do estado vibracional (EV)? | C12: =IF(D12, "Sim", "") | D12: FALSE
A13: 10. Holochacra. Já a ajudei a equilibrar e flexibilizar o próprio holochacra? | C13: =IF(D13, "Sim", "") | D13: FALSE
A14: 11. Holorgasmo. Já procurei dar-lhe, pelo menos, um holorgasmo (raro) até o momento? | C14: =IF(D14, "Sim", "") | D14: FALSE
A15: 12. Isca. Já servi de isca consciencial lúcida a fim de promover os desassédios dela? | C15: =IF(D15, "Sim", "") | D15: FALSE
... A28: 25. Trafores. Já fiz uma exposição sincera dos megatrafores, ou trafores que já identifiquei nela ou dela, a fim de que ela os empregue no combate aos seus trafares pessoais? | C28: =IF(D28, "Sim", "") | D28: FALSE
A30: Se o interessado ou interessada respondeu sim a, pelo menos, 12 destas questões, a sua afetividade prática ou vivida, é de bom nível conscienciológico, holossomático e parapsíquico. | B30: Total | C30: =F30 -> 0 | E30: Sim | F30: =COUNTIF(C4:C28, "sim") -> 0
E31: Não | F31: =25-F30 -> 25

Sheet Comparativo Autent. Afetiva
B1: COMPARATIVO DA AUTENCIDADE AFETIVA DA DUPLA
B3: # | C3: HOMEM | D3: VARIÁVEIS | E3: MULHER | G3: Convergências
C4: ='Autenticidade Afetiva Homem'!C4 | D4: Acoplamento | E4: ='Autenticidade Afetiva Mulher'!C4 | G4: =IF(K4=2, "Convergência", " ") | I4: =IF(C4="sim", "1", "0") -> 0 | J4: =IF(E4="sim", "1", "0") -> 0 | K4: =COUNTIF(I4:J4, "1") -> 0
B5: 1 | C5: ='Autenticidade Afetiva Homem'!C5 | D5: Alcova | E5: ='Autenticidade Afetiva Mulher'!C5 | G5: =IF(K5=2, "Convergência", " ") | I5: =IF(C5="sim", "1", "0") -> 0 | J5: =IF(E5="sim", "1", "0") -> 0 | K5: =COUNTIF(I5:J5, "1") -> 0
B6: 2 | C6: ='Autenticidade Afetiva Homem'!C6 | D6: Assédios | E6: ='Autenticidade Afetiva Mulher'!C6 | G6: =IF(K6=2, "Convergência", " ") | I6: =IF(C6="sim", "1", "0") -> 0 | J6: =IF(E6="sim", "1", "0") -> 0 | K6: =COUNTIF(I6:J6, "1") -> 0
B7: 3 | C7: ='Autenticidade Afetiva Homem'!C7 | D7: Assins | E7: ='Autenticidade Afetiva Mulher'!C7 | G7: =IF(K7=2, "Convergência", " ") | I7: =IF(C7="sim", "1", "0") -> 0 | J7: =IF(E7="sim", "1", "0") -> 0 | K7: =COUNTIF(I7:J7, "1") -> 0
B8: 4 | C8: ='Autenticidade Afetiva Homem'!C8 | D8: Carinho | E8: ='Autenticidade Afetiva Mulher'!C8 | G8: =IF(K8=2, "Convergência", " ") | I8: =IF(C8="sim", "1", "0") -> 0 | J8: =IF(E8="sim", "1", "0") -> 0 | K8: =COUNTIF(I8:J8, "1") -> 0
B9: 5 | C9: ='Autenticidade Afetiva Homem'!C9 | D9: Clarividências | E9: ='Autenticidade Afetiva Mulher'!C9 | G9: =IF(K9=2, "Convergência", " ") | I9: =IF(C9="sim", "1", "0") -> 0 | J9: =IF(E9="sim", "1", "0") -> 0 | K9: =COUNTIF(I9:J9, "1") -> 0
B10: 6 | C10: ='Autenticidade Afetiva Homem'!C10 | D10: Cosmoconsciência | E10: ='Autenticidade Afetiva Mulher'!C10 | G10: =IF(K10=2, "Convergência", " ") | I10: =IF(C10="sim", "1", "0") -> 0 | J10: =IF(E10="sim", "1", "0") -> 0 | K10: =COUNTIF(I10:J10, "1") -> 0
B11: 7 | C11: ='Autenticidade Afetiva Homem'!C11 | D11: Descompensações | E11: ='Autenticidade Afetiva Mulher'!C11 | G11: =IF(K11=2, "Convergência", " ") | I11: =IF(C11="sim", "1", "0") -> 0 | J11: =IF(E11="sim", "1", "0") -> 0 | K11: =COUNTIF(I11:J11, "1") -> 0
B12: 8 | C12: ='Autenticidade Afetiva Homem'!C12 | D12: Estado Vibracional | E12: ='Autenticidade Afetiva Mulher'!C12 | G12: =IF(K12=2, "Convergência", " ") | I12: =IF(C12="sim", "1", "0") -> 0 | J12: =IF(E12="sim", "1", "0") -> 0 | K12: =COUNTIF(I12:J12, "1") -> 0
B13: 9 | C13: ='Autenticidade Afetiva Homem'!C13 | D13: Holochacra | E13: ='Autenticidade Afetiva Mulher'!C13 | G13: =IF(K13=2, "Convergência", " ") | I13: =IF(C13="sim", "1", "0") -> 0 | J13: =IF(E13="sim", "1", "0") -> 0 | K13: =COUNTIF(I13:J13, "1") -> 0
B14: 10 | C14: ='Autenticidade Afetiva Homem'!C14 | D14: Holorgasmo | E14: ='Autenticidade Afetiva Mulher'!C14 | G14: =IF(K14=2, "Convergência", " ") | I14: =IF(C14="sim", "1", "0") -> 0 | J14: =IF(E14="sim", "1", "0") -> 0 | K14: =COUNTIF(I14:J14, "1") -> 0
B15: 11 | C15: ='Autenticidade Afetiva Homem'!C15 | D15: Isca | E15: ='Autenticidade Afetiva Mulher'!C15 | G15: =IF(K15=2, "Convergência", " ") | I15: =IF(C15="sim", "1", "0") -> 0 | J15: =IF(E15="sim", "1", "0") -> 0 | K15: =COUNTIF(I15:J15, "1") -> 0
B16: 12 | C16: ='Autenticidade Afetiva Homem'!C16 | D16: Objetos | E16: ='Autenticidade Afetiva Mulher'!C16 | G16: =IF(K16=2, "Convergência", " ") | I16: =IF(C16="sim", "1", "0") -> 0 | J16: =IF(E16="sim", "1", "0") -> 0 | K16: =COUNTIF(I16:J16, "1") -> 0
... B28: 24 | C28: ='Autenticidade Afetiva Homem'!C28 | D28: Trafores | E28: ='Autenticidade Afetiva Mulher'!C28 | G28: =IF(K28=2, "Convergência", " ") | I28: =IF(C28="sim", "1", "0") -> 0 | J28: =IF(E28="sim", "1", "0") -> 0 | K28: =COUNTIF(I28:J28, "1") -> 0
B31: Se o interessado ou interessada respondeu sim a, pelo menos, 12 destas questões, a sua afetividade prática ou vivida, é de bom nível conscienciológico, holossomático e parapsíquico.
C34: Resultado
C35: Convergência | D35: =COUNTIF(G4:G28, "convergência") -> 0
C36: Divergência | D36: =25-D35 -> 25

Sheet Dupla é
B1: A DUPLA EVOLUTIVA É
B3: Através do mentalsoma, podemos embasar os princípios da dupla evolutiva capazes de alcançar pleno êxito na vida humana, estabelecendo as características inteligentes e cosmoéticas da vivência humana, evolutiva, a dois, através de um teste.
B5: Eis um teste com 30 características pelas quais podemos saber o que a dupla evolutiva satisfatória é, e, ao mesmo tempo, o que a dupla evolutiva não é:
B7: Em caso positivo, marque com "x", na coluna "Assinalar", a questão correspondente.
B9: A Dupla Evolutiva É: | F9: Assinalar | H9: A Dupla Evolutiva NÃO É: | K9: Assinalar
B11: 1. Almoçar e jantar sabendo com quem | H11: 1, Ajuste entre 2 conscins estranhas
B12: 2. Apoio mútuo nas obras conscienciais | H12: 2. Anulação efêmera de 2 conscins
B13: 3. Compartilhar intimidade autêntica | H13: 3. Atendimento da necessidade de ter filhos
B14: 4. Compreensão mútua profunda | H14: 4. Camisa de força a dois na Socin
B15: 5. Compromisso ímpar de destino | H15: 5. Casamento fechado tradicional
B16: 6. Crescimento evolutivo a dois | H16: 6. Coleira apertada no pescoço
B17: 7. Cumplicidade grupocármica lúcida | H17: 7. Desligamento da comunicação
B18: 8. Fazer amor puro com envolvimento | H18: 8. Destruição da individualidade
B19: 9. Interdependência consciente sadia | H19: 9. Distanciamento emocional
B20: 10. Intimidade para realizações dignas | H20: 10. Divórcio emocional pelo psicossoma
B21: 11. Método perene de ensaio e erro | H21: 11. Proposta de cada um na sua
B22: 12. Morar no holossoma do outro(a) | H22: 12. Ficar sem conversar entre si
... B42: Resultado da Primeira Coluna | H42: Resultado da Segunda Coluna
C43: =COUNTIF(F11:F40, "x") -> 0 | I43: =COUNTIF(K11:K40, "x") -> 0
C46: =C43/30 -> 0 | I46: =I43/30 -> 0
C49: As características da dupla evolutiva que você compõe, predominam na primeira ou na segunda coluna do teste?

Sheet 15 Ideias Básicas
A1: IDEIAS BÁSICAS DA DUPLA EVOLUTIVA
A3: Em uma abordagem pela ordem alfabética dos assuntos, eis 15 ideais básicos da dupla evolutiva, seja constituída por 2 inversores, 2 reciclantes, ou uma dupla mista, reciclante / inversor (a), ou vice-versa. Qual o percentual de aplicabilidade da dupla nas ideias básicas mencionadas?
A5: 1. Afetividade. Estima, amor e afetividade decorrentes de todos os esforços conjuntos a fim de queimar etapas em busca da evolução consciencial. | G5: 1 | H5: 1 | I5: 1 | J5: 1 | K5: 1 | L5: 1 | M5: 1 | N5: 1 | O5: 1 | P5: 1 | Q5: 1 | R5: 1 | S5: 1 | T5: 1 | U5: 1 | W5: Afetividade | X5: =((G$5-1)*25)/100 -> 0
A6: 2. Conduta. Espontaneidade desinibida, o ato de tirar a maquilagem, a autenticidade sincera e permanente dentro da conduta cosmoética, intrafísica e extrafísica. | G6: 0 | H6: 0 | I6: 0 | J6: 0 | K6: 0 | L6: 0 | M6: 0 | N6: 0 | O6: 0 | P6: 0 | Q6: 0 | R6: 0 | S6: 0 | T6: 0 | U6: 0 | W6: Conduta | X6: =((H$5-1)*25)/100 -> 0
A7: 3. Confiança. Confiança aberta, mútua, que elimina a insegurança do ciúme doentio, através do diálogo ou da intercomunicação consciencial ininterrupta. | G7: 0.25 | H7: 0.25 | I7: 0.25 | J7: 0.25 | K7: 0.25 | L7: 0.25 | M7: 0.25 | N7: 0.25 | O7: 0.25 | P7: 0.25 | Q7: 0.25 | R7: 0.25 | S7: 0.25 | T7: 0.25 | U7: 0.25 | W7: Confiança | X7: =((I$5-1)*25)/100 -> 0
A8: 4. Criatividade. Criatividade com expansão em tudo o que se faz, consciente do caráter avançado e original dos princípios da filosofia da dupla evolutiva. | G8: 0.5 | H8: 0.5 | I8: 0.5 | J8: 0.5 | K8: 0.5 | L8: 0.5 | M8: 0.5 | N8: 0.5 | O8: 0.5 | P8: 0.5 | Q8: 0.5 | R8: 0.5 | S8: 0.5 | T8: 0.5 | U8: 0.5 | W8: Criatividade | X8: =((J$5-1)*25)/100 -> 0
A9: 5. ECs. Amor revitalizante no sistema de energias conscienciais (ECs) abertas, a dois, em expansão viva. | G9: 0.75 | H9: 0.75 | I9: 0.75 | J9: 0.75 | K9: 0.75 | L9: 0.75 | M9: 0.75 | N9: 0.75 | O9: 0.75 | P9: 0.75 | Q9: 0.75 | R9: 0.75 | S9: 0.75 | T9: 0.75 | U9: 0.75 | W9: Ecs | X9: =((K$5-1)*25)/100 -> 0
A10: 6. Enriquecimento. Enriquecimento consciencial efetivo tanto para um quanto para o outro parceiro consciencial, intrafísico, evolutivo, consciente. | G10: 1 | H10: 1 | I10: 1 | J10: 1 | K10: 1 | L10: 1 | M10: 1 | N10: 1 | O10: 1 | P10: 1 | Q10: 1 | R10: 1 | S10: 1 | T10: 1 | U10: 1 | W10: Enriquecimento | X10: =((L$5-1)*25)/100 -> 0
A11: 7. Estimulação. Estimulação recíproca, sem sufocações ou chantagens emocionais. | W11: Estimulação | X11: =((M$5-1)*25)/100 -> 0
A12: 8. Evolução. Respeito natural ao nível e ao ritmo evolutivo do companheiro (ou companheira), na verdade, a maior demonstração prática de amor puro. | W12: Evolução | X12: =((N$5-1)*25)/100 -> 0
A13: 9. Flexibilidade. Flexibilidade mental prática nos papéis vitais que cada um desempenha em uma existência agilizada pelo discernimento magno. | W13: Flexibilidade | X13: =((O$5-1)*25)/100 -> 0
A14: 10. Imediatismo. Crescimento pessoal e conjunto com potencialidade ilimitada no aqui-e-agora do imediatismo diferente, holossomático, multidimensional e lúcido. | W14: Imediatismo | X14: =((P$5-1)*25)/100 -> 0
A15: 11. Interdependência. Liberdade individual dentro da condição lúcida da interdependência evolutiva, distante da dependência e independência conscienciais impraticáveis ou inconvenientes. | W15: Interdependência | X15: =((Q$5-1)*25)/100 -> 0
A16: 12. Intimidade. Intimidade máxima possível entre 2 conscins, pré-serenonas, que demandam a condição evoluída do desassediado permanente total (desperto). | W16: Intimidade | X16: =((R$5-1)*25)/100 -> 0
A17: 13. Mudanças. Aprendizagem evolutiva incessante sempre adaptável às mudanças esperadas e compreensíveis que se fizerem necessárias. | W17: Mudanças | X17: =((S$5-1)*25)/100 -> 0
A18: 14. Relacionamento. Intensidade positiva do relacionamento, com expectativas realistas e racionais, sem escravidão de qualquer natureza. | W18: Relacionamento | X18: =((T$5-1)*25)/100 -> 0
A19: 15. Responsabilidades. Responsabilidade pessoal e conjunta, a dois, perante as próprias proéxis, ou as programações existenciais e evolutivas. | W19: Responsabilidades | X19: =((U$5-1)*25)/100 -> 0
W21: Média | X21: =AVERAGE(X5:X19) -> 0
A43: Aplicabilidade média das ideias básicas é de | B43: =X21 -> 0 | C43: Ideias básicas com 100% são | D43: =COUNTIF(X5:X19, "100%") -> 0
A45: Se você compõe com alguém uma dupla evolutiva com 10 destes itens ideais, a possibilidade de êxito do seu convívio libertário, em dupla, está assegurada.

Sheet Pontecialidades
A1: POTENCIALIDADES A SEREM CONQUISTADAS PELA DUPLA EVOLUTIVA
A3: Eis como exemplos, em ordem alfabética, dentre outras, 60 potencialidades, realizações, execuções, empreendimentos exequíveis ou vivências mútuas, sadias, alcançadas pela dupla evolutiva em sua evolução consciencial, na vida intra e extrafísica a dois (universo dual), condutas-exceção sadias com os seus somas, holochacras, psicossomas e mentaissomas quando conjugados:
A5: 1. Acoplamentos áuricos profiláticos a dois. | G5: =IF(H5, "Sim", "") | H5: FALSE | I5: 31. Minimortes temporárias vividas a dois (projeções). | P5: =IF(Q5, "Sim", "") | Q5: FALSE
A6: 2. Assistências interconscienciais a dois. | G6: =IF(H6, "Sim", "") | H6: FALSE | I6: 32. Moréxis simultâneas obtidas a dois no mesmo período. | P6: =IF(Q6, "Sim", "") | Q6: FALSE
A7: 3. Atacadismo consciencial exercido a dois. | G7: =IF(H7, "Sim", "") | H7: FALSE | I7: 33. Parapsiquismo desenvolvido e exercido a dois. | P7: =IF(Q7, "Sim", "") | Q7: FALSE
A8: 4. Ato de ficar sozinho a dois. | G8: =IF(H8, "Sim", "") | H8: FALSE | I8: 34. Pensenizações cosmoéticas a dois (ho' a dois. | P8: =IF(Q8, "Sim", "") | Q8: FALSE
A9: 5. Compléxis alcançados em décadas a dois. | G9: =IF(H9, "Sim", "") | H9: FALSE | I9: 35. Policarmalidade buscada e vivida a dois. | P9: =IF(Q9, "Sim", "") | Q9: FALSE
A10: 6. Conscienciograma consultado a dois. | G10: =IF(H10, "Sim", "") | H10: FALSE | I10: 36. Primaveras energéticas usufruídas a dois. | P10: =IF(Q10, "Sim", "") | Q10: FALSE
A11: 7. Conscientização multidimensional a dois. | G11: =IF(H11, "Sim", "") | H11: FALSE | I11: 37. Proéxis executadas e exemplificadas a dois. | P11: =IF(Q11, "Sim", "") | Q11: FALSE
A12: 8. Correções de erros e omissões deficitárias a dois. | G12: =IF(H12, "Sim", "") | H12: FALSE | I12: 38. Profissão semelhante exercida a dois. | P12: =IF(Q12, "Sim", "") | Q12: FALSE
A13: 9. Cosmoética vivida a dois (incorruptibilidade). | G13: =IF(H13, "Sim", "") | H13: FALSE | I13: 39. Projeções conscientes conjuntas a dois. | P13: =IF(Q13, "Sim", "") | Q13: FALSE
A14: 10. Crescimento evolutivo desenvolvido a dois. | G14: =IF(H14, "Sim", "") | H14: FALSE | I14: 40. Projetarium construído e empregado a dois. | P14: =IF(Q14, "Sim", "") | Q14: FALSE
A15: 11. Desperticidade produtiva e usufruída a dois. | G15: =IF(H15, "Sim", "") | H15: FALSE | I15: 41. Recéxis analisadas e desenvolvidas a dois. | P15: =IF(Q15, "Sim", "") | Q15: FALSE
A16: 12. Dimener alcançada com lucidez a dois | G16: =IF(H16, "Sim", "") | H16: FALSE | I16: 42. Recuperações simultâneas dos cons a dois. | P16: =IF(Q16, "Sim", "") | Q16: FALSE
... A33: 29. Lazer com motivação e trabalho construtivo a dois. | G33: =IF(H33, "Sim", "") | H33: FALSE | I33: 59. Volitações lúcidas experimentadas a dois. | P33: =IF(Q33, "Sim", "") | Q33: FALSE
A34: 30. Liberdade máxima vivida a dois na Socin. | G34: =IF(H34, "Sim", "") | H34: FALSE
A36: Você, leitor ou leitora, já alcançou quantas e quais conquistas, desta listagem, com o seu parceiro de dupla evolutiva?
B43: Realizadas | C43: =COUNTIF(H5:H34, "verdadeiro")+COUNTIF(Q5:Q33, "verdadeiro") -> 0
B44: Não realizadas | C44: =COUNTIF(H5:H34, "falso")+COUNTIF(Q5:Q33, "falsa") -> 0

Sheet Amor Consciencial Homem
A1: ESTADO DO AMOR CONSCIENCIAL PURO - HOMEM
A3: É possível diagnosticar o estado do amor consciencial puro - fisiológico e parafisiológico - da dupla evolutiva, através de 15 sinais insofismáveis, a médio e longo prazo:
A5: 1. Admiração. Você está fascinado pela visão da pessoa, embevecido ao máximo em sua admiração? | G5: 1 | H5: 1 | I5: 1 | J5: 1 | K5: 1 | L5: 1 | M5: 1 | N5: 1 | O5: 1 | P5: 1 | Q5: 1 | R5: 1 | S5: 1 | T5: 1 | U5: 1 | W5: Admiração | X5: =((G$5-1)*25)/100 -> 0
A6: 2. Bem-estar. Inclina-se pela pessoa com um sentimento inefável de bem-estar? | G6: 0 | H6: 0 | I6: 0 | J6: 0 | K6: 0 | L6: 0 | M6: 0 | N6: 0 | O6: 0 | P6: 0 | Q6: 0 | R6: 0 | S6: 0 | T6: 0 | U6: 0 | W6: Bem-estar | X6: =((H$5-1)*25)/100 -> 0
A7: 3. ECs. Tem o anseio de ficar só, em silêncio e sem quaisquer reclamações, no ambiente pessoal até o outro dia, quando sabe que a pessoa retornará ali, em função das energias conscienciais alimentadoras dela, aí existentes, percebidas e usufruídas por você? | G7: 0.25 | H7: 0.25 | I7: 0.25 | J7: 0.25 | K7: 0.25 | L7: 0.25 | M7: 0.25 | N7: 0.25 | O7: 0.25 | P7: 0.25 | Q7: 0.25 | R7: 0.25 | S7: 0.25 | T7: 0.25 | U7: 0.25 | W7: Ecs | X7: =((I$5-1)*25)/100 -> 0
A8: 4. Euforia. Você devora o ser-alvo com os olhos cheios das melhores lágrimas de alegria, no auge da euforia possível, em toda a sua existência intrafísica? | G8: 0.5 | H8: 0.5 | I8: 0.5 | J8: 0.5 | K8: 0.5 | L8: 0.5 | M8: 0.5 | N8: 0.5 | O8: 0.5 | P8: 0.5 | Q8: 0.5 | R8: 0.5 | S8: 0.5 | T8: 0.5 | U8: 0.5 | W8: Euforia | X8: =((J$5-1)*25)/100 -> 0
A9: 5. Expectativas. As suas expectativas positivas estão exacerbadas para melhor? | G9: 0.75 | H9: 0.75 | I9: 0.75 | J9: 0.75 | K9: 0.75 | L9: 0.75 | M9: 0.75 | N9: 0.75 | O9: 0.75 | P9: 0.75 | Q9: 0.75 | R9: 0.75 | S9: 0.75 | T9: 0.75 | U9: 0.75 | W9: Expectativas | X9: =((K$5-1)*25)/100 -> 0
A10: 6. Impetuosidades. Você passa por ímpetos, difíceis de serem contidos, de envolvimento físico e ternura contínua com a presença e a proximidade dessa pessoa? | G10: 1 | H10: 1 | I10: 1 | J10: 1 | K10: 1 | L10: 1 | M10: 1 | N10: 1 | O10: 1 | P10: 1 | Q10: 1 | R10: 1 | S10: 1 | T10: 1 | U10: 1 | W10: Impetuosidades | X10: =((L$5-1)*25)/100 -> 0
A11: 7. Megaparaíso. Você vive no último céu, com o megaparaíso na Terra e, se pudesse, faria as pedras chorarem de emoção? | W11: Megaparaíso | X11: =((M$5-1)*25)/100 -> 0
A12: 8. Plenitude. Você está de espírito desafogado, em um supremo estado de excitação, plenitude e bem-aventurança, em um nível sobre o qual jamais sonhara antes? | W12: Plenitude | X12: =((N$5-1)*25)/100 -> 0
A13: 9. Presença. Você se sente como se o ar, a atmosfera e a própria luz do ambiente mudassem para melhor com a simples presença dessa pessoa? | W13: Presença | X13: =((O$5-1)*25)/100 -> 0
A14: 10. Primener. Você contempla tudo cor-de-rosa, vivendo no mundo encantado, mágico, da primener, desejando gritar de alegria para todos os seres vivos e a tudo contagiar? | W14: Primener | X14: =((P$5-1)*25)/100 -> 0
A15: 11. Sensibilidade. Você acordou a própria sensibilidade, que estava adormecida - e não sabia - tocado nos pontos mais nevrálgicos da sua personalidade afetiva? | W15: Sensibilidade | X15: =((Q$5-1)*25)/100 -> 0
A16: 12. Sentimento. Você sente bem desse alguém, com todos os enternecimentos do mundo? | W16: Sentimento | X16: =((R$5-1)*25)/100 -> 0
A17: 13. Sincronicidades. Você percebe sincronicidades a respeito da pessoa, e até quanto ao nome dela, que se intensifica de maneira envolvente, por toda parte, em torno de você? | W17: Sincronicidades | X17: =((S$5-1)*25)/100 -> 0
A18: 14. Ternura. Você se comove, com ternura insofreável, até o fundo de si, assoberbado pelas emoções mais felizes e mais sadias que não se lembra de ter experimentado antes? | W18: Ternura | X18: =((T$5-1)*25)/100 -> 0
A19: 15. Valorização. Ocorre para você uma valorização irreprimível, inédita e inesperada, dos objetos e seres do ambiente onde a pessoa esteve até há poucos instantes? | W19: Valorização | X19: =((U$5-1)*25)/100 -> 0
W21: Média | X21: =AVERAGE(X5:X19) -> 0
A43: Aplicabilidade média de | B43: =X21 -> 0 | C43: do estado de amor consciencial puro

Sheet Amor Consciencial Mulher
A1: ESTADO DO AMOR CONSCIENCIAL PURO - MULHER
A3: É possível diagnosticar o estado do amor consciencial puro - fisiológico e parafisiológico - da dupla evolutiva, através de 15 sinais insofismáveis, a médio e longo prazo:
A5: 1. Admiração. Você está fascinado pela visão da pessoa, embevecido ao máximo em sua admiração? | G5: 1 | H5: 1 | I5: 1 | J5: 1 | K5: 1 | L5: 1 | M5: 1 | N5: 1 | O5: 1 | P5: 1 | Q5: 1 | R5: 1 | S5: 1 | T5: 1 | U5: 1 | W5: Admiração | X5: =((G$5-1)*25)/100 -> 0
A6: 2. Bem-estar. Inclina-se pela pessoa com um sentimento inefável de bem-estar? | G6: 0 | H6: 0 | I6: 0 | J6: 0 | K6: 0 | L6: 0 | M6: 0 | N6: 0 | O6: 0 | P6: 0 | Q6: 0 | R6: 0 | S6: 0 | T6: 0 | U6: 0 | W6: Bem-estar | X6: =((H$5-1)*25)/100 -> 0
A7: 3. ECs. Tem o anseio de ficar só, em silêncio e sem quaisquer reclamações, no ambiente pessoal até o outro dia, quando sabe que a pessoa retornará ali, em função das energias conscienciais alimentadoras dela, aí existentes, percebidas e usufruídas por você? | G7: 0.25 | H7: 0.25 | I7: 0.25 | J7: 0.25 | K7: 0.25 | L7: 0.25 | M7: 0.25 | N7: 0.25 | O7: 0.25 | P7: 0.25 | Q7: 0.25 | R7: 0.25 | S7: 0.25 | T7: 0.25 | U7: 0.25 | W7: Ecs | X7: =((I$5-1)*25)/100 -> 0
A8: 4. Euforia. Você devora o ser-alvo com os olhos cheios das melhores lágrimas de alegria, no auge da euforia possível, em toda a sua existência intrafísica? | G8: 0.5 | H8: 0.5 | I8: 0.5 | J8: 0.5 | K8: 0.5 | L8: 0.5 | M8: 0.5 | N8: 0.5 | O8: 0.5 | P8: 0.5 | Q8: 0.5 | R8: 0.5 | S8: 0.5 | T8: 0.5 | U8: 0.5 | W8: Euforia | X8: =((J$5-1)*25)/100 -> 0
A9: 5. Expectativas. As suas expectativas positivas estão exacerbadas para melhor? | G9: 0.75 | H9: 0.75 | I9: 0.75 | J9: 0.75 | K9: 0.75 | L9: 0.75 | M9: 0.75 | N9: 0.75 | O9: 0.75 | P9: 0.75 | Q9: 0.75 | R9: 0.75 | S9: 0.75 | T9: 0.75 | U9: 0.75 | W9: Expectativas | X9: =((K$5-1)*25)/100 -> 0
A10: 6. Impetuosidades. Você passa por ímpetos, difíceis de serem contidos, de envolvimento físico e ternura contínua com a presença e a proximidade dessa pessoa? | G10: 1 | H10: 1 | I10: 1 | J10: 1 | K10: 1 | L10: 1 | M10: 1 | N10: 1 | O10: 1 | P10: 1 | Q10: 1 | R10: 1 | S10: 1 | T10: 1 | U10: 1 | W10: Impetuosidades | X10: =((L$5-1)*25)/100 -> 0
A11: 7. Megaparaíso. Você vive no último céu, com o megaparaíso na Terra e, se pudesse, faria as pedras chorarem de emoção? | W11: Megaparaíso | X11: =((M$5-1)*25)/100 -> 0
A12: 8. Plenitude. Você está de espírito desafogado, em um supremo estado de excitação, plenitude e bem-aventurança, em um nível sobre o qual jamais sonhara antes? | W12: Plenitude | X12: =((N$5-1)*25)/100 -> 0
A13: 9. Presença. Você se sente como se o ar, a atmosfera e a própria luz do ambiente mudassem para melhor com a simples presença dessa pessoa? | W13: Presença | X13: =((O$5-1)*25)/100 -> 0
A14: 10. Primener. Você contempla tudo cor-de-rosa, vivendo no mundo encantado, mágico, da primener, desejando gritar de alegria para todos os seres vivos e a tudo contagiar? | W14: Primener | X14: =((P$5-1)*25)/100 -> 0
A15: 11. Sensibilidade. Você acordou a própria sensibilidade, que estava adormecida - e não sabia - tocado nos pontos mais nevrálgicos da sua personalidade afetiva? | W15: Sensibilidade | X15: =((Q$5-1)*25)/100 -> 0
A16: 12. Sentimento. Você sente bem desse alguém, com todos os enternecimentos do mundo? | W16: Sentimento | X16: =((R$5-1)*25)/100 -> 0
A17: 13. Sincronicidades. Você percebe sincronicidades a respeito da pessoa, e até quanto ao nome dela, que se intensifica de maneira envolvente, por toda parte, em torno de você? | W17: Sincronicidades | X17: =((S$5-1)*25)/100 -> 0
A18: 14. Ternura. Você se comove, com ternura insofreável, até o fundo de si, assoberbado pelas emoções mais felizes e mais sadias que não se lembra de ter experimentado antes? | W18: Ternura | X18: =((T$5-1)*25)/100 -> 0
A19: 15. Valorização. Ocorre para você uma valorização irreprimível, inédita e inesperada, dos objetos e seres do ambiente onde a pessoa esteve até há poucos instantes? | W19: Valorização | X19: =((U$5-1)*25)/100 -> 0
W21: Média | X21: =AVERAGE(X5:X19) -> 0
A43: Aplicabilidade média de | B43: =X21 -> 0 | C43: do estado de amor consciencial puro

Sheet Comparativo Amor Consciencial
B1: COMPARATIVO DO ESTADO DO AMOR CONSCIENCIAL PURO DA DUPLA EVOLUTIVA
B2: O parceiro ou a parceira da dupla evolutiva que sentir até as proximidades destas realidades descritas, aqui, em poucas palavras, está com a sua afetividade fisiológica e parafisiologicamente em seu mais alto grau de realização. Vale a pena, a esta altura, valorizar a união e buscar ao máximo amadurecê-la em ambos os parceiros, se for possível.
